{"name": "test_dos", "status": "broken", "statusDetails": {"message": "ExceptionGroup: errors while tearing down <Module Fixture_decorate2.py> (2 sub-exceptions)", "trace": "+ Exception Group Traceback (most recent call last):\n  |   File \"C:\\Users\\saul.frias\\PycharmProjects\\SeleniumProject\\.venv\\Lib\\site-packages\\_pytest\\runner.py\", line 341, in from_call\n  |     result: TResult | None = func()\n  |                              ~~~~^^\n  |   File \"C:\\Users\\saul.frias\\PycharmProjects\\SeleniumProject\\.venv\\Lib\\site-packages\\_pytest\\runner.py\", line 242, in <lambda>\n  |     lambda: runtest_hook(item=item, **kwds), when=when, reraise=reraise\n  |             ~~~~~~~~~~~~^^^^^^^^^^^^^^^^^^^\n  |   File \"C:\\Users\\saul.frias\\PycharmProjects\\SeleniumProject\\.venv\\Lib\\site-packages\\pluggy\\_hooks.py\", line 512, in __call__\n  |     return self._hookexec(self.name, self._hookimpls.copy(), kwargs, firstresult)\n  |            ~~~~~~~~~~~~~~^^^^^^^^^^^^^^^^^^^^^^^^^^^^^^^^^^^^^^^^^^^^^^^^^^^^^^^^\n  |   File \"C:\\Users\\saul.frias\\PycharmProjects\\SeleniumProject\\.venv\\Lib\\site-packages\\pluggy\\_manager.py\", line 120, in _hookexec\n  |     return self._inner_hookexec(hook_name, methods, kwargs, firstresult)\n  |            ~~~~~~~~~~~~~~~~~~~~^^^^^^^^^^^^^^^^^^^^^^^^^^^^^^^^^^^^^^^^^\n  |   File \"C:\\Users\\saul.frias\\PycharmProjects\\SeleniumProject\\.venv\\Lib\\site-packages\\pluggy\\_callers.py\", line 167, in _multicall\n  |     raise exception\n  |   File \"C:\\Users\\saul.frias\\PycharmProjects\\SeleniumProject\\.venv\\Lib\\site-packages\\pluggy\\_callers.py\", line 139, in _multicall\n  |     teardown.throw(exception)\n  |     ~~~~~~~~~~~~~~^^^^^^^^^^^\n  |   File \"C:\\Users\\saul.frias\\PycharmProjects\\SeleniumProject\\.venv\\Lib\\site-packages\\_pytest\\threadexception.py\", line 97, in pytest_runtest_teardown\n  |     yield from thread_exception_runtest_hook()\n  |   File \"C:\\Users\\saul.frias\\PycharmProjects\\SeleniumProject\\.venv\\Lib\\site-packages\\_pytest\\threadexception.py\", line 68, in thread_exception_runtest_hook\n  |     yield\n  |   File \"C:\\Users\\saul.frias\\PycharmProjects\\SeleniumProject\\.venv\\Lib\\site-packages\\pluggy\\_callers.py\", line 139, in _multicall\n  |     teardown.throw(exception)\n  |     ~~~~~~~~~~~~~~^^^^^^^^^^^\n  |   File \"C:\\Users\\saul.frias\\PycharmProjects\\SeleniumProject\\.venv\\Lib\\site-packages\\_pytest\\unraisableexception.py\", line 100, in pytest_runtest_teardown\n  |     yield from unraisable_exception_runtest_hook()\n  |   File \"C:\\Users\\saul.frias\\PycharmProjects\\SeleniumProject\\.venv\\Lib\\site-packages\\_pytest\\unraisableexception.py\", line 70, in unraisable_exception_runtest_hook\n  |     yield\n  |   File \"C:\\Users\\saul.frias\\PycharmProjects\\SeleniumProject\\.venv\\Lib\\site-packages\\pluggy\\_callers.py\", line 139, in _multicall\n  |     teardown.throw(exception)\n  |     ~~~~~~~~~~~~~~^^^^^^^^^^^\n  |   File \"C:\\Users\\saul.frias\\PycharmProjects\\SeleniumProject\\.venv\\Lib\\site-packages\\_pytest\\logging.py\", line 853, in pytest_runtest_teardown\n  |     yield from self._runtest_for(item, \"teardown\")\n  |   File \"C:\\Users\\saul.frias\\PycharmProjects\\SeleniumProject\\.venv\\Lib\\site-packages\\_pytest\\logging.py\", line 829, in _runtest_for\n  |     yield\n  |   File \"C:\\Users\\saul.frias\\PycharmProjects\\SeleniumProject\\.venv\\Lib\\site-packages\\pluggy\\_callers.py\", line 139, in _multicall\n  |     teardown.throw(exception)\n  |     ~~~~~~~~~~~~~~^^^^^^^^^^^\n  |   File \"C:\\Users\\saul.frias\\PycharmProjects\\SeleniumProject\\.venv\\Lib\\site-packages\\pluggy\\_callers.py\", line 53, in run_old_style_hookwrapper\n  |     return result.get_result()\n  |            ~~~~~~~~~~~~~~~~~^^\n  |   File \"C:\\Users\\saul.frias\\PycharmProjects\\SeleniumProject\\.venv\\Lib\\site-packages\\pluggy\\_result.py\", line 103, in get_result\n  |     raise exc.with_traceback(tb)\n  |   File \"C:\\Users\\saul.frias\\PycharmProjects\\SeleniumProject\\.venv\\Lib\\site-packages\\pluggy\\_callers.py\", line 38, in run_old_style_hookwrapper\n  |     res = yield\n  |           ^^^^^\n  |   File \"C:\\Users\\saul.frias\\PycharmProjects\\SeleniumProject\\.venv\\Lib\\site-packages\\pluggy\\_callers.py\", line 139, in _multicall\n  |     teardown.throw(exception)\n  |     ~~~~~~~~~~~~~~^^^^^^^^^^^\n  |   File \"C:\\Users\\saul.frias\\PycharmProjects\\SeleniumProject\\.venv\\Lib\\site-packages\\_pytest\\capture.py\", line 903, in pytest_runtest_teardown\n  |     return (yield)\n  |             ^^^^^\n  |   File \"C:\\Users\\saul.frias\\PycharmProjects\\SeleniumProject\\.venv\\Lib\\site-packages\\pluggy\\_callers.py\", line 121, in _multicall\n  |     res = hook_impl.function(*args)\n  |   File \"C:\\Users\\saul.frias\\PycharmProjects\\SeleniumProject\\.venv\\Lib\\site-packages\\_pytest\\runner.py\", line 189, in pytest_runtest_teardown\n  |     item.session._setupstate.teardown_exact(nextitem)\n  |     ~~~~~~~~~~~~~~~~~~~~~~~~~~~~~~~~~~~~~~~^^^^^^^^^^\n  |   File \"C:\\Users\\saul.frias\\PycharmProjects\\SeleniumProject\\.venv\\Lib\\site-packages\\_pytest\\runner.py\", line 557, in teardown_exact\n  |     raise exceptions[0]\n  | ExceptionGroup: errors while tearing down <Module Fixture_decorate2.py> (2 sub-exceptions)\n  +-+---------------- 1 ----------------\n    | Traceback (most recent call last):\n    |   File \"C:\\Users\\saul.frias\\PycharmProjects\\SeleniumProject\\.venv\\Lib\\site-packages\\_pytest\\runner.py\", line 546, in teardown_exact\n    |     fin()\n    |     ~~~^^\n    |   File \"C:\\Users\\saul.frias\\PycharmProjects\\SeleniumProject\\.venv\\Lib\\site-packages\\_pytest\\fixtures.py\", line 1032, in finish\n    |     raise exceptions[0]\n    |   File \"C:\\Users\\saul.frias\\PycharmProjects\\SeleniumProject\\.venv\\Lib\\site-packages\\_pytest\\fixtures.py\", line 1021, in finish\n    |     fin()\n    |     ~~~^^\n    |   File \"C:\\Users\\saul.frias\\PycharmProjects\\SeleniumProject\\.venv\\Lib\\site-packages\\allure_commons\\_allure.py\", line 231, in __call__\n    |     return self._fixture_function(*args, **kwargs)\n    |            ~~~~~~~~~~~~~~~~~~~~~~^^^^^^^^^^^^^^^^^\n    |   File \"C:\\Users\\saul.frias\\PycharmProjects\\SeleniumProject\\.venv\\Lib\\site-packages\\_pytest\\fixtures.py\", line 907, in _teardown_yield_fixture\n    |     next(it)\n    |     ~~~~^^^^\n    |   File \"C:\\Users\\saul.frias\\PycharmProjects\\SeleniumProject\\PYTEST\\Fixture_decorate2.py\", line 41, in setup_login_uno\n    |     driver.close()\n    |     ~~~~~~~~~~~~^^\n    |   File \"C:\\Users\\saul.frias\\PycharmProjects\\SeleniumProject\\.venv\\Lib\\site-packages\\selenium\\webdriver\\remote\\webdriver.py\", line 579, in close\n    |     self.execute(Command.CLOSE)\n    |     ~~~~~~~~~~~~^^^^^^^^^^^^^^^\n    |   File \"C:\\Users\\saul.frias\\PycharmProjects\\SeleniumProject\\.venv\\Lib\\site-packages\\selenium\\webdriver\\remote\\webdriver.py\", line 429, in execute\n    |     self.error_handler.check_response(response)\n    |     ~~~~~~~~~~~~~~~~~~~~~~~~~~~~~~~~~^^^^^^^^^^\n    |   File \"C:\\Users\\saul.frias\\PycharmProjects\\SeleniumProject\\.venv\\Lib\\site-packages\\selenium\\webdriver\\remote\\errorhandler.py\", line 232, in check_response\n    |     raise exception_class(message, screen, stacktrace)\n    | selenium.common.exceptions.InvalidSessionIdException: Message: Tried to run command without establishing a connection\n    | \n    +---------------- 2 ----------------\n    | Traceback (most recent call last):\n    |   File \"C:\\Users\\saul.frias\\PycharmProjects\\SeleniumProject\\.venv\\Lib\\site-packages\\_pytest\\runner.py\", line 546, in teardown_exact\n    |     fin()\n    |     ~~~^^\n    |   File \"C:\\Users\\saul.frias\\PycharmProjects\\SeleniumProject\\.venv\\Lib\\site-packages\\_pytest\\fixtures.py\", line 1032, in finish\n    |     raise exceptions[0]\n    |   File \"C:\\Users\\saul.frias\\PycharmProjects\\SeleniumProject\\.venv\\Lib\\site-packages\\_pytest\\fixtures.py\", line 1021, in finish\n    |     fin()\n    |     ~~~^^\n    |   File \"C:\\Users\\saul.frias\\PycharmProjects\\SeleniumProject\\.venv\\Lib\\site-packages\\allure_commons\\_allure.py\", line 231, in __call__\n    |     return self._fixture_function(*args, **kwargs)\n    |            ~~~~~~~~~~~~~~~~~~~~~~^^^^^^^^^^^^^^^^^\n    |   File \"C:\\Users\\saul.frias\\PycharmProjects\\SeleniumProject\\.venv\\Lib\\site-packages\\_pytest\\fixtures.py\", line 907, in _teardown_yield_fixture\n    |     next(it)\n    |     ~~~~^^^^\n    |   File \"C:\\Users\\saul.frias\\PycharmProjects\\SeleniumProject\\PYTEST\\Fixture_decorate2.py\", line 56, in setup_Login_dos\n    |     driver.close()\n    |     ~~~~~~~~~~~~^^\n    |   File \"C:\\Users\\saul.frias\\PycharmProjects\\SeleniumProject\\.venv\\Lib\\site-packages\\selenium\\webdriver\\remote\\webdriver.py\", line 579, in close\n    |     self.execute(Command.CLOSE)\n    |     ~~~~~~~~~~~~^^^^^^^^^^^^^^^\n    |   File \"C:\\Users\\saul.frias\\PycharmProjects\\SeleniumProject\\.venv\\Lib\\site-packages\\selenium\\webdriver\\remote\\webdriver.py\", line 429, in execute\n    |     self.error_handler.check_response(response)\n    |     ~~~~~~~~~~~~~~~~~~~~~~~~~~~~~~~~~^^^^^^^^^^\n    |   File \"C:\\Users\\saul.frias\\PycharmProjects\\SeleniumProject\\.venv\\Lib\\site-packages\\selenium\\webdriver\\remote\\errorhandler.py\", line 232, in check_response\n    |     raise exception_class(message, screen, stacktrace)\n    | selenium.common.exceptions.InvalidSessionIdException: Message: Tried to run command without establishing a connection\n    | \n    +------------------------------------"}, "attachments": [{"name": "Customer2", "source": "79216457-cff3-4ce8-a472-ac6e7fd01670-attachment.png", "type": "image/png"}, {"name": "stdout", "source": "24e0548d-7673-4d46-9be0-11828102cdd0-attachment.txt", "type": "text/plain"}], "start": 1751938075774, "stop": 1751938081487, "uuid": "ec4c38ab-5b16-48d9-a637-c2af2782159c", "historyId": "406cfa9035396ee7f94e99a42a510c8a", "testCaseId": "406cfa9035396ee7f94e99a42a510c8a", "fullName": "Fixture_decorate2#test_dos", "labels": [{"name": "suite", "value": "Fixture_decorate2"}, {"name": "host", "value": "LAM48"}, {"name": "thread", "value": "26728-MainThread"}, {"name": "framework", "value": "pytest"}, {"name": "language", "value": "cpython3"}, {"name": "package", "value": "Fixture_decorate2"}]}